<robot
  name="dummy_ardop3">


  <link
    name="base_link">
    <inertial>
      <origin
        xyz="0.14406 -0.37484 0.49172"
        rpy="0 0 0" />
      <mass
        value="63.062" />
      <inertia
        ixx="0"
        ixy="0"
        ixz="0"
        iyy="0"
        iyz="0"
        izz="0" />
    </inertial>
    <visual>
      <origin
        xyz="0 0 0"
        rpy="0 0 0" />
      <geometry>
        <mesh
          filename="package://dummy_ardop3/meshes/base_link.STL" />
      </geometry>
      <material
        name="">
        <color
          rgba="0.79216 0.81961 0.93333 1" />
      </material>
    </visual>
    <collision>
      <origin
        xyz="0 0 0"
        rpy="0 0 0" />
      <geometry>
        <mesh
          filename="package://dummy_ardop3/meshes/base_link.STL" />
      </geometry>
    </collision>
  </link>



  
  <link
    name="shoulder1_Link">
    <inertial>
      <origin
        xyz="-0.016887 0.043943 0.032845"
        rpy="0 0 0" />
      <mass
        value="0.2086" />
      <inertia
        ixx="0"
        ixy="0"
        ixz="0"
        iyy="0"
        iyz="0"
        izz="0"/>
    </inertial>
    <visual>
      <origin
        xyz="0 0 0"
        rpy="0 0 0" />
      <geometry>
        <mesh
          filename="package://dummy_ardop3/meshes/shoulder1_Link.STL" />
      </geometry>
      <material
        name="">
        <color
          rgba="0.79216 0.81961 0.93333 1" />
      </material>
    </visual>
    <collision>
      <origin
        xyz="0 0 0"
        rpy="0 0 0" />
      <geometry>
        <mesh
          filename="package://dummy_ardop3/meshes/shoulder1_Link.STL" />
      </geometry>
    </collision>
  </link>
  <joint
    name="shoulder1_joint"
    type="revolute">
    <origin
      xyz="0.13068 -0.13412 1.0671"
      rpy="1.5708 -2.1406E-14 -3.0739" />
    <parent
      link="base_link" />
    <child
      link="shoulder1_Link" />
    <axis
      xyz="0 1 0" />
    <limit
      effort="0"
      velocity="0" />
  </joint>
  <link
    name="shoulder2_Link">
    <inertial>
      <origin
        xyz="-0.0038766 -0.0035371 -0.028659"
        rpy="0 0 0" />
      <mass
        value="0.10212" />
      <inertia
        ixx="0"
        ixy="0"
        ixz="0"
        iyy="0"
        iyz="0"
        izz="0" />
    </inertial>
    <visual>
      <origin
        xyz="0 0 0"
        rpy="0 0 0" />
      <geometry>
        <mesh
          filename="package://dummy_ardop3/meshes/shoulder2_Link.STL" />
      </geometry>
      <material
        name="">
        <color
          rgba="0.79216 0.81961 0.93333 1" />
      </material>
    </visual>
    <collision>
      <origin
        xyz="0 0 0"
        rpy="0 0 0" />
      <geometry>
        <mesh
          filename="package://dummy_ardop3/meshes/shoulder2_Link.STL" />
      </geometry>
    </collision>
  </link>
  <joint
    name="shoulder2_joint"
    type="revolute">
    <origin
      xyz="-0.0026622 0.04 0.067457"
      rpy="3.1416 -2.6433E-14 1.584" />
    <parent
      link="shoulder1_Link" />
    <child
      link="shoulder2_Link" />
    <axis
      xyz="0 0 1" />
    <limit
      effort="0"
      velocity="0" />
  </joint>
  <link
    name="bicep_Link">
    <inertial>
      <origin
        xyz="0.0070764 -0.0020983 0.042877"
        rpy="0 0 0" />
      <mass
        value="0.58962" />
      <inertia
        ixx="0"
        ixy="0"
        ixz="0"
        iyy="0"
        iyz="0"
        izz="0" />
    </inertial>
    <visual>
      <origin
        xyz="0 0 0"
        rpy="0 0 0" />
      <geometry>
        <mesh
          filename="package://dummy_ardop3/meshes/bicep_Link.STL" />
      </geometry>
      <material
        name="">
        <color
          rgba="0.79216 0.81961 0.93333 1" />
      </material>
    </visual>
    <collision>
      <origin
        xyz="0 0 0"
        rpy="0 0 0" />
      <geometry>
        <mesh
          filename="package://dummy_ardop3/meshes/bicep_Link.STL" />
      </geometry>
    </collision>
  </link>
  <joint
    name="bicep_joint"
    type="revolute">
    <origin
      xyz="-0.088746 0.0073113 -0.043438"
      rpy="-1.5708 1.5169 -3.1416" />
    <parent
      link="shoulder2_Link" />
    <child
      link="bicep_Link" />
    <axis
      xyz="-0.11857 0.04839 0.99177" />
    <limit
      effort="0"
      velocity="0" />
  </joint>
  <link
    name="forearm_Link">
    <inertial>
      <origin
        xyz="0.041651 -0.11116 0.028209"
        rpy="0 0 0" />
      <mass
        value="0.4986" />
      <inertia
        ixx="0"
        ixy="0"
        ixz="0"
        iyy="0"
        iyz="0"
        izz="0" />
    </inertial>
    <visual>
      <origin
        xyz="0 0 0"
        rpy="0 0 0" />
      <geometry>
        <mesh
          filename="package://dummy_ardop3/meshes/forearm_Link.STL" />
      </geometry>
      <material
        name="">
        <color
          rgba="0.79216 0.81961 0.93333 1" />
      </material>
    </visual>
    <collision>
      <origin
        xyz="0 0 0"
        rpy="0 0 0" />
      <geometry>
        <mesh
          filename="package://dummy_ardop3/meshes/forearm_Link.STL" />
      </geometry>
    </collision>
  </link>
  <joint
    name="forearm_joint"
    type="revolute">
    <origin
      xyz="0 -0.11676 0.024047"
      rpy="-0.01322 2.7339E-15 -1.9429E-16" />
    <parent
      link="bicep_Link" />
    <child
      link="forearm_Link" />
    <axis
      xyz="-1 0 0" />
    <limit
      effort="0"
      velocity="0" />
  </joint>
  <link
    name="holder_Link">
    <inertial>
      <origin
        xyz="-0.018663 0.044904 0.018187"
        rpy="0 0 0" />
      <mass
        value="0.10431" />
      <inertia
 		ixx="0"
        ixy="0"
        ixz="0"
        iyy="0"
        iyz="0"
        izz="0" />
    </inertial>
    <visual>
      <origin
        xyz="0 0 0"
        rpy="0 0 0" />
      <geometry>
        <mesh
          filename="package://dummy_ardop3/meshes/holder_Link.STL" />
      </geometry>
      <material
        name="">
        <color
          rgba="0.79216 0.81961 0.93333 1" />
      </material>
    </visual>
    <collision>
      <origin
        xyz="0 0 0"
        rpy="0 0 0" />
      <geometry>
        <mesh
          filename="package://dummy_ardop3/meshes/holder_Link.STL" />
      </geometry>
    </collision>
  </link>
  <joint
    name="holder_joint"
    type="revolute">
    <origin
      xyz="0.0021411 -0.22718 0"
      rpy="1.5708 1.5024 -5.887E-15" />
    <parent
      link="forearm_Link" />
    <child
      link="holder_Link" />
    <axis
      xyz="0 0 -1" />
    <limit
      effort="0"
      velocity="0" />
  </joint>
  <link
    name="endeffector_Link">
    <inertial>
      <origin
        xyz="0.096458 -0.02348 -0.059948"
        rpy="0 0 0" />
      <mass
        value="0.30399" />
      <inertia
        ixx="0"
        ixy="0"
        ixz="0"
        iyy="0"
        iyz="0"
        izz="0"/>
    </inertial>
    <visual>
      <origin
        xyz="0 0 0"
        rpy="0 0 0" />
      <geometry>
        <mesh
          filename="package://dummy_ardop3/meshes/endeffector_Link.STL" />
      </geometry>
      <material
        name="">
        <color
          rgba="0.75294 0.75294 0.75294 1" />
      </material>
    </visual>
    <collision>
      <origin
        xyz="0 0 0"
        rpy="0 0 0" />
      <geometry>
        <mesh
          filename="package://dummy_ardop3/meshes/endeffector_Link.STL" />
      </geometry>
    </collision>
  </link>
  <joint
    name="endeffector_joint"
    type="revolute">
    <origin
      xyz="0.0098589 0.019849 0.019818"
      rpy="-3.1379 4.1633E-17 1.5708" />
    <parent
      link="holder_Link" />
    <child
      link="endeffector_Link" />
    <axis
      xyz="-1 0 0" />
    <limit
      effort="0"
      velocity="0" />
  </joint>
  <link
    name="wheel_front_left_Link">
    <inertial>
      <origin
        xyz="-0.0075 1.223E-16 -2.6201E-14"
        rpy="0 0 0" />
      <mass
        value="0.01907" />
      <inertia
        ixx="0"
        ixy="0"
        ixz="0"
        iyy="0"
        iyz="0"
        izz="0" />
    </inertial>
    <visual>
      <origin
        xyz="0 0 0"
        rpy="0 0 0" />
      <geometry>
        <mesh
          filename="package://dummy_ardop3/meshes/wheel_front_left_Link.STL" />
      </geometry>
      <material
        name="">
        <color
          rgba="0.75294 0.75294 0.75294 1" />
      </material>
    </visual>
    <collision>
      <origin
        xyz="0 0 0"
        rpy="0 0 0" />
      <geometry>
        <mesh
          filename="package://dummy_ardop3/meshes/wheel_front_left_Link.STL" />
      </geometry>
    </collision>
  </link>
  <joint
    name="wheel_front_left_joint"
    type="continuous">
    <origin
      xyz="-0.0057681 -0.56485 0.18409"
      rpy="-3.1345 6.0618E-17 1.5708" />
    <parent
      link="base_link" />
    <child
      link="wheel_front_left_Link" />
    <axis
      xyz="-1 0 0" />
  </joint>
  <link
    name="wheel_front_right_Link">
    <inertial>
      <origin
        xyz="-0.0075 2.7756E-17 3.2651E-14"
        rpy="0 0 0" />
      <mass
        value="0.01907" />
      <inertia
        ixx="0"
        ixy="0"
        ixz="0"
        iyy="0"
        iyz="0"
        izz="0" />
    </inertial>
    <visual>
      <origin
        xyz="0 0 0"
        rpy="0 0 0" />
      <geometry>
        <mesh
          filename="package://dummy_ardop3/meshes/wheel_front_right_Link.STL" />
      </geometry>
      <material
        name="">
        <color
          rgba="0.75294 0.75294 0.75294 1" />
      </material>
    </visual>
    <collision>
      <origin
        xyz="0 0 0"
        rpy="0 0 0" />
      <geometry>
        <mesh
          filename="package://dummy_ardop3/meshes/wheel_front_right_Link.STL" />
      </geometry>
    </collision>
  </link>
  <joint
    name="wheel_front_right_joint"
    type="continuous">
    <origin
      xyz="-0.0057681 -0.16985 0.18409"
      rpy="1.5708 6.123E-17 1.5708" />
    <parent
      link="base_link" />
    <child
      link="wheel_front_right_Link" />
    <axis
      xyz="-1 0 0" />
  </joint>
  <link
    name="wheel_back_left_Link">
    <inertial>
      <origin
        xyz="-0.0075 5.5511E-17 3.2585E-14"
        rpy="0 0 0" />
      <mass
        value="0.01907" />
      <inertia
        ixx="0"
        ixy="0"
        ixz="0"
        iyy="0"
        iyz="0"
        izz="0" />
    </inertial>
    <visual>
      <origin
        xyz="0 0 0"
        rpy="0 0 0" />
      <geometry>
        <mesh
          filename="package://dummy_ardop3/meshes/wheel_back_left_Link.STL" />
      </geometry>
      <material
        name="">
        <color
          rgba="0.75294 0.75294 0.75294 1" />
      </material>
    </visual>
    <collision>
      <origin
        xyz="0 0 0"
        rpy="0 0 0" />
      <geometry>
        <mesh
          filename="package://dummy_ardop3/meshes/wheel_back_left_Link.STL" />
      </geometry>
    </collision>
  </link>
  <joint
    name="wheel_back_left_joint"
    type="continuous">
    <origin
      xyz="0.31038 -0.56485 0.18409"
      rpy="1.5708 6.123E-17 1.5708" />
    <parent
      link="base_link" />
    <child
      link="wheel_back_left_Link" />
    <axis
      xyz="-1 0 0" />
  </joint>
  <link
    name="wheel_back_right_Link">
    <inertial>
      <origin
        xyz="-0.0075 -2.7756E-17 3.2585E-14"
        rpy="0 0 0" />
      <mass
        value="0.01907" />
      <inertia
        ixx="0"
        ixy="0"
        ixz="0"
        iyy="0"
        iyz="0"
        izz="0" />
    </inertial>
    <visual>
      <origin
        xyz="0 0 0"
        rpy="0 0 0" />
      <geometry>
        <mesh
          filename="package://dummy_ardop3/meshes/wheel_back_right_Link.STL" />
      </geometry>
      <material
        name="">
        <color
          rgba="0.75294 0.75294 0.75294 1" />
      </material>
    </visual>
    <collision>
      <origin
        xyz="0 0 0"
        rpy="0 0 0" />
      <geometry>
        <mesh
          filename="package://dummy_ardop3/meshes/wheel_back_right_Link.STL" />
      </geometry>
    </collision>
  </link>
  <joint
    name="wheel_back_right_joint"
    type="continuous">
    <origin
      xyz="0.31038 -0.16985 0.18409"
      rpy="1.5708 6.123E-17 1.5708" />
    <parent
      link="base_link" />
    <child
      link="wheel_back_right_Link" />
    <axis
      xyz="-1 0 0" />
  </joint>
</robot>